<h1>正确地使用异常</h1>

<h2>理由</h2>

1. 当处理错误的代码与通过一个或多个中间函数调用检测错误的代码分离时，请使用异常
2. 对于每个可能引发或传播异常的函数，请提供三项异常保证之一：强保证、基本保证或无故障保证
3. 通过值引发异常，通过引用捕获异常
4. 不要使用 C++11 中已弃用的异常规范
5. 使用适用的标准库异常类型。 从 `exception` 类层次结构派生自定义的异常类型
6. 默认构造函数、析构函数、`swap` 函数，`move` 操作符都不应该抛出异常

<h2>讨论</h2>


<h3>三个异常保证</h3>

<h4>无故障保证</h4>

此保证声明，该函数将不会引发异常或允许异常传播。此时，应将函数声明为 `noexcept` ，以让编译器最大程度的优化函数，如减少执行路径，提高错误退出的效率。如：
`vector` 等STL容器，为了保证接口的健壮性，如果保存元素的 `move` 运算符没有声明为 `noexcept`，则在容器扩张搬移元素时不会使用 `move` 机制，而使用 `copy` 机制，带来性能损失的风险。

如果一个函数不能抛出异常，或者一个程序并没有截获某个函数所抛出的异常并进行处理，那么这个函数可以用新的 `noexcept` 关键字对其进行修饰，表示这个函数不会抛出异常或者抛出的异常不会被截获并处理。例如：

    // 即使可能抛出异常，也可以使用 noexcept
    // 这里不准备处理内存耗尽的异常，简单地将函数声明为noexcept
    std::vector<int> MyComputation(const std::vector<int>& v) noexcept
    {
        std::vector<int> res = v;    // 可能会抛出异常
        // do something
        return res;
    }

<h4>增强保证</h4>
增强保证声明，如果函数因异常超出范围，则将不会泄漏内存并且不会修改程序状态。 一个提供增强保证的函数主要是一个提交或回滚语义的事务：它要么完全成功，要么无任何效果。

<h4>基本保证</h4>
基本保证是三个保证是最弱的一个。 但是，当增强保证对于内存消耗或性能来说很昂贵时，此保证可能是最佳选择。 基本保证声明，如果出现异常，内存不会泄漏并且对象将仍处于可用状态，即使可能已修改数据仍是如此。


<h3>通过值引发异常并通过常数引用将其捕获</h3>

    MyData md;
    try {
        md = GetNetworkResource();
    } catch (const networkIOException& e) {
        cerr << e.what();
    } catch (const myDataFormatException& e) {
        cerr << e.what();
    }

    MyData GetNetworkResource()
    {
    if (IOSuccess == false)
        throw networkIOException("Unable to connect");
    if (readError)
        throw myDataFormatException("Format error");
    }

 如果 `catch` 语句指定省略号 `(...)` 而非类型，则 `catch` 程序块将处理每种类型的异常。 由于 `catch` 程序块按编程顺序处理来查找匹配类型，所以尽量不要使用省略号处理程序来处理关联的 `try` 程序块。请谨慎使用 `catch(...)`；除非 `catch` 块知道如何处理捕获的特定异常，否则禁止程序继续执行。 `catch(...)` 块一般用于在程序停止执行前记录错误和执行特殊的清理工作。

 <h3>未处理的异常</h3>

 如果无法找到当前异常的匹配处理程序（或省略号 `catch` 处理程序），则调用预定义的 `terminate` 运行时函数。`terminate` 的默认操作是调用 `abort`。 如果你希望 `terminate` 在退出应用程序之前调用程序中的某些其他函数，则用被调用函数的名称作为其单个自变量调用 `set_terminate` 函数。 您可以在程序的任何点调用 `set_terminate`。 `terminate` 例程总是调用指定为 `set_terminate` 的参数的最后一个函数。

    #include <iostream>
    using namespace std;
    void term_func()
    {
        cout << "term_func was called by terminate." << endl;
        exit( -1 );
    }

    int main() {
        try {
            set_terminate( term_func );
            throw "Out of memory!";
        } catch( int ) {
            cout << "Integer exception raised." << endl;
        }
        return 0;
    }